Workbook

Sheet Support
A1: Column1 | B1: Column2 | C1: Column3 | D1: Column4 | E1: Column5
A2: ticket_id | B2: review_id | C2: product_id | D2: complaint_category | E2: resolution
A3: T0001 | B3: R0081 | C3: P057 | D3: Wrong item | E3: Resolved
A4: T0002 | B4: R0025 | C4: P009 | D4: Product quality | E4: Resolved
A5: T0003 | B5: R0173 | C5: P049 | D5: Product quality | E5: Escalated
A6: T0004 | B6: R0188 | C6: P049 | D6: Wrong item | E6: Pending
A7: T0005 | B7: R0148 | C7: P012 | D7: Late delivery | E7: Resolved
A8: T0006 | B8: R0048 | C8: P003 | D8: Refund issue | E8: Resolved
A9: T0007 | B9: R0075 | C9: P005 | D9: Refund issue | E9: Resolved
A10: T0008 | B10: R0037 | C10: P012 | D10: Late delivery | E10: Resolved
A11: T0009 | B11: R0049 | C11: P027 | D11: Wrong item | E11: Resolved
A12: T0010 | B12: R0145 | C12: P051 | D12: Product quality | E12: Resolved
... A72: T0070 | B72: R0086 | C72: P040 | D72: Damaged item | E72: Pending

Sheet Orders
A1: order_id | B1: review_id | C1: delivery_days | D1: discount_percent | E1: return_flag | F1: product_id
A2: O0001 | B2: R0189 | C2: 2 | D2: 20 | E2: TRUE | F2: P018
A3: O0002 | B3: R0154 | C3: 5 | D3: 20 | E3: FALSE | F3: P002
A4: O0003 | B4: R0164 | C4: 6 | D4: 20 | E4: FALSE | F4: P010
A5: O0004 | B5: R0125 | C5: 3 | D5: 15 | E5: FALSE | F5: P056
A6: O0005 | B6: R0043 | C6: 2 | D6: 10 | E6: FALSE | F6: P021
A7: O0006 | B7: R0026 | C7: 6 | D7: 20 | E7: FALSE | F7: P006
A8: O0007 | B8: R0136 | C8: 5 | D8: 30 | E8: TRUE | F8: P052
A9: O0008 | B9: R0168 | C9: 3 | D9: 25 | E9: FALSE | F9: P028
A10: O0009 | B10: R0138 | C10: 7 | D10: 5 | E10: FALSE | F10: P010
A11: O0010 | B11: R0137 | C11: 5 | D11: 10 | E11: TRUE | F11: P055
A12: O0011 | B12: R0109 | C12: 8 | D12: 10 | E12: FALSE | F12: P048
A13: O0012 | B13: R0119 | C13: 5 | D13: 5 | E13: FALSE | F13: P009
... A196: O0195 | B196: R0054 | C196: 7 | D196: 30 | E196: FALSE | F196: P034

Sheet Sellers
A1: seller_id | B1: seller_name | C1: region | D1: tenure_years
A2: S001 | B2: Seller_01 | C2: South | D2: 11
A3: S002 | B3: Seller_02 | C3: South | D3: 7
A4: S003 | B4: Seller_03 | C4: Central | D4: 9
A5: S004 | B5: Seller_04 | C5: North | D5: 3
A6: S005 | B6: Seller_05 | C6: West | D6: 1
A7: S006 | B7: Seller_06 | C7: Central | D7: 9
A8: S007 | B8: Seller_07 | C8: South | D8: 11
A9: S008 | B9: Seller_08 | C9: West | D9: 4
A10: S009 | B10: Seller_09 | C10: West | D10: 12
A11: S010 | B11: Seller_10 | C11: South | D11: 12
A12: S011 | B12: Seller_11 | C12: North | D12: 11
A13: S012 | B13: Seller_12 | C13: South | D13: 3
... A16: S015 | B16: Seller_15 | C16: West | D16: 6

Sheet Products
A1: Column1 | B1: Column2 | C1: Column3 | D1: Column4 | E1: Column5
A2: product_id | B2: category | C2: brand | D2: price_band | E2: seller_id
A3: P001 | B3: Electronics | C3: NovaTech | D3: Premium | E3: S001
A4: P002 | B4: Home | C4: NestWell | D4: Premium | E4: S005
A5: P003 | B5: Beauty | C5: DermaLeaf | D5: Mid-range | E5: S009
A6: P004 | B6: Sports | C6: ActivePeak | D6: Mid-range | E6: S008
A7: P005 | B7: Books | C7: Readify | D7: Mid-range | E7: S006
A8: P006 | B8: Electronics | C8: ByteWorks | D8: Premium | E8: S007
A9: P007 | B9: Home | C9: CasaCo | D9: Premium | E9: S004
A10: P008 | B10: Beauty | C10: GlowLab | D10: Premium | E10: S005
A11: P009 | B11: Sports | C11: ActivePeak | D11: Premium | E11: S007
A12: P010 | B12: Books | C12: InkHouse | D12: Mid-range | E12: S003
... A62: P060 | B62: Books | C62: PageTurner | D62: Mid-range | E62: S005

Sheet Sheet2
A3: Row Labels | B3: Average of rating
A4: Beauty | B4: 3.4444444
A5: Books | B5: 3.516129 | G5: Average Rating by Product Category
A6: Electronics | B6: 3.1071429
A7: Home | B7: 3.3055556
A8: Sports | B8: 3.2413793
A9: Grand Total | B9: 3.3174603

Sheet Sheet6
A3: Row Labels | B3: Average of rating
A4: FALSE | B4: 3.4831461
A5: TRUE | B5: 3.17 | G5: Verified vs Unverified Ratings
A6: Grand Total | B6: 3.3174603

Sheet Sheet8
A3: Row Labels | B3: Average of rating
A4: 1 | B4: 4
A5: 2 | B5: 3.25
A6: 3 | B6: 3.2619048 | G6: Average Rating by Delivery Days
A7: 4 | B7: 3.1842105
A8: 5 | B8: 3.5666667
A9: 6 | B9: 3.0555556
A10: 7 | B10: 3.2
A11: 8 | B11: 3.3846154
A12: 9 | B12: 4
A13: Grand Total | B13: 3.3174603

Sheet Summary
A1: PRODUCT REVIEW INSIGHT
A3: KEY BUSINESS INSIGHTS
A4: Overall Average Rating | B4: 3.32 / 5
A5: Highest Rated Category | B5: Books – 3.52 / 5
A6: Lowest Rated Category | B6: Electronics – 3.11 / 5
A7: Verified Review Average | B7: 3.17 / 5
A8: Unverified Review Average | B8: 3.48 / 5

Sheet Reviews
A1: review_id | B1: product_id | C1: rating | D1: review_length | E1: verified | F1: review_date | G1: long_review_flag | H1: category | I1: delivery_days
A2: R0189 | B2: P018 | C2: 5 | D2: 26 | E2: TRUE | F2: 45779 | G2: FALSE | H2: =_xlfn.XLOOKUP(B2,Products!A:A,Products!B:B,"Not Found") -> Beauty | I2: =_xlfn.XLOOKUP(A2,Orders!B:B,Orders!C:C,"Not Found") -> 2
A3: R0154 | B3: P002 | C3: 4 | D3: 24 | E3: FALSE | F3: 45788 | G3: FALSE | H3: =_xlfn.XLOOKUP(B3,Products!A:A,Products!B:B,"Not Found") -> Home | I3: =_xlfn.XLOOKUP(A3,Orders!B:B,Orders!C:C,"Not Found") -> 5
A4: R0164 | B4: P010 | C4: 3 | D4: 136 | E4: TRUE | F4: 45808 | G4: TRUE | H4: =_xlfn.XLOOKUP(B4,Products!A:A,Products!B:B,"Not Found") -> Books | I4: =_xlfn.XLOOKUP(A4,Orders!B:B,Orders!C:C,"Not Found") -> 6
A5: R0125 | B5: P056 | C5: 2 | D5: 48 | E5: TRUE | F5: 45662 | G5: FALSE | H5: =_xlfn.XLOOKUP(B5,Products!A:A,Products!B:B,"Not Found") -> Electronics | I5: =_xlfn.XLOOKUP(A5,Orders!B:B,Orders!C:C,"Not Found") -> 3
A6: R0043 | B6: P021 | C6: 5 | D6: 30 | E6: TRUE | F6: 45895 | G6: FALSE | H6: =_xlfn.XLOOKUP(B6,Products!A:A,Products!B:B,"Not Found") -> Electronics | I6: =_xlfn.XLOOKUP(A6,Orders!B:B,Orders!C:C,"Not Found") -> 2
A7: R0026 | B7: P006 | C7: 4 | D7: 62 | E7: TRUE | F7: 45777 | G7: FALSE | H7: =_xlfn.XLOOKUP(B7,Products!A:A,Products!B:B,"Not Found") -> Electronics | I7: =_xlfn.XLOOKUP(A7,Orders!B:B,Orders!C:C,"Not Found") -> 6
A8: R0136 | B8: P052 | C8: 1 | D8: 20 | E8: FALSE | F8: 45701 | G8: FALSE | H8: =_xlfn.XLOOKUP(B8,Products!A:A,Products!B:B,"Not Found") -> Home | I8: =_xlfn.XLOOKUP(A8,Orders!B:B,Orders!C:C,"Not Found") -> 5
A9: R0168 | B9: P028 | C9: 4 | D9: 28 | E9: FALSE | F9: 45979 | G9: FALSE | H9: =_xlfn.XLOOKUP(B9,Products!A:A,Products!B:B,"Not Found") -> Beauty | I9: =_xlfn.XLOOKUP(A9,Orders!B:B,Orders!C:C,"Not Found") -> 3
A10: R0138 | B10: P010 | C10: 5 | D10: 32 | E10: FALSE | F10: 45889 | G10: FALSE | H10: =_xlfn.XLOOKUP(B10,Products!A:A,Products!B:B,"Not Found") -> Books | I10: =_xlfn.XLOOKUP(A10,Orders!B:B,Orders!C:C,"Not Found") -> 7
A11: R0137 | B11: P055 | C11: 2 | D11: 27 | E11: TRUE | F11: 45940 | G11: FALSE | H11: =_xlfn.XLOOKUP(B11,Products!A:A,Products!B:B,"Not Found") -> Books | I11: =_xlfn.XLOOKUP(A11,Orders!B:B,Orders!C:C,"Not Found") -> 5
A12: R0109 | B12: P048 | C12: 4 | D12: 16 | E12: FALSE | F12: 45693 | G12: FALSE | H12: =_xlfn.XLOOKUP(B12,Products!A:A,Products!B:B,"Not Found") -> Beauty | I12: =_xlfn.XLOOKUP(A12,Orders!B:B,Orders!C:C,"Not Found") -> 8
A13: R0119 | B13: P009 | C13: 5 | D13: 45 | E13: TRUE | F13: 45740 | G13: FALSE | H13: =_xlfn.XLOOKUP(B13,Products!A:A,Products!B:B,"Not Found") -> Sports | I13: =_xlfn.XLOOKUP(A13,Orders!B:B,Orders!C:C,"Not Found") -> 5
... A41: R0006 | B41: P039 | C41: 1 | D41: 49 | E41: TRUE | F41: 45897 | G41: FALSE | H41: =_xlfn.XLOOKUP(B41,Products!A:A,Products!B:B,"Not Found") -> Sports | I41: =_xlfn.XLOOKUP(A41,Orders!B:B,Orders!C:C,"Not Found") -> 3
A42: R0112 | B42: P049 | D42: 52 | E42: TRUE | F42: 45953 | G42: FALSE | H42: =_xlfn.XLOOKUP(B42,Products!A:A,Products!B:B,"Not Found") -> Sports | I42: =_xlfn.XLOOKUP(A42,Orders!B:B,Orders!C:C,"Not Found") -> 2
A43: R0067 | B43: P001 | C43: 3 | D43: 37 | E43: TRUE | F43: 45935 | G43: FALSE | H43: =_xlfn.XLOOKUP(B43,Products!A:A,Products!B:B,"Not Found") -> Electronics | I43: =_xlfn.XLOOKUP(A43,Orders!B:B,Orders!C:C,"Not Found") -> 8
A44: R0068 | B44: P051 | C44: 5 | D44: 93 | E44: FALSE | F44: 45772 | G44: FALSE | H44: =_xlfn.XLOOKUP(B44,Products!A:A,Products!B:B,"Not Found") -> Electronics | I44: =_xlfn.XLOOKUP(A44,Orders!B:B,Orders!C:C,"Not Found") -> 3
A45: R0139 | B45: P042 | C45: 4 | D45: 36 | E45: TRUE | F45: 45763 | G45: FALSE | H45: =_xlfn.XLOOKUP(B45,Products!A:A,Products!B:B,"Not Found") -> Home | I45: =_xlfn.XLOOKUP(A45,Orders!B:B,Orders!C:C,"Not Found") -> 2
A46: R0147 | B46: P013 | C46: 4 | D46: 120 | E46: TRUE | F46: 45953 | G46: FALSE | H46: =_xlfn.XLOOKUP(B46,Products!A:A,Products!B:B,"Not Found") -> Beauty | I46: =_xlfn.XLOOKUP(A46,Orders!B:B,Orders!C:C,"Not Found") -> 6
A47: R0162 | B47: P040 | C47: 4 | D47: 68 | E47: FALSE | F47: 45812 | G47: FALSE | H47: =_xlfn.XLOOKUP(B47,Products!A:A,Products!B:B,"Not Found") -> Books | I47: =_xlfn.XLOOKUP(A47,Orders!B:B,Orders!C:C,"Not Found") -> 3
A48: R0061 | B48: P044 | C48: 4 | D48: 19 | E48: TRUE | F48: 45725 | G48: FALSE | H48: =_xlfn.XLOOKUP(B48,Products!A:A,Products!B:B,"Not Found") -> Sports | I48: =_xlfn.XLOOKUP(A48,Orders!B:B,Orders!C:C,"Not Found") -> 3
A49: R0015 | B49: P029 | C49: 4 | D49: 20 | E49: FALSE | F49: 45904 | G49: FALSE | H49: =_xlfn.XLOOKUP(B49,Products!A:A,Products!B:B,"Not Found") -> Sports | I49: =_xlfn.XLOOKUP(A49,Orders!B:B,Orders!C:C,"Not Found") -> 3
A50: R0072 | B50: P020 | C50: 3 | D50: 30 | E50: TRUE | F50: 45705 | G50: FALSE | H50: =_xlfn.XLOOKUP(B50,Products!A:A,Products!B:B,"Not Found") -> Books | I50: =_xlfn.XLOOKUP(A50,Orders!B:B,Orders!C:C,"Not Found") -> 4
A51: R0032 | B51: P024 | C51: 3 | D51: 16 | E51: FALSE | F51: 45906 | G51: FALSE | H51: =_xlfn.XLOOKUP(B51,Products!A:A,Products!B:B,"Not Found") -> Sports | I51: =_xlfn.XLOOKUP(A51,Orders!B:B,Orders!C:C,"Not Found") -> 4
A52: R0151 | B52: P024 | C52: 3 | D52: 186 | E52: FALSE | F52: 45931 | G52: TRUE | H52: =_xlfn.XLOOKUP(B52,Products!A:A,Products!B:B,"Not Found") -> Sports | I52: =_xlfn.XLOOKUP(A52,Orders!B:B,Orders!C:C,"Not Found") -> 8
A53: R0143 | B53: P058 | C53: 4 | D53: 65 | E53: TRUE | F53: 45723 | G53: FALSE | H53: =_xlfn.XLOOKUP(B53,Products!A:A,Products!B:B,"Not Found") -> Beauty | I53: =_xlfn.XLOOKUP(A53,Orders!B:B,Orders!C:C,"Not Found") -> 5
A54: R0003 | B54: P019 | C54: 5 | D54: 69 | E54: FALSE | F54: 45683 | G54: FALSE | H54: =_xlfn.XLOOKUP(B54,Products!A:A,Products!B:B,"Not Found") -> Sports | I54: =_xlfn.XLOOKUP(A54,Orders!B:B,Orders!C:C,"Not Found") -> 4
A55: R0011 | B55: P017 | C55: 5 | D55: 45 | E55: TRUE | F55: 45846 | G55: FALSE | H55: =_xlfn.XLOOKUP(B55,Products!A:A,Products!B:B,"Not Found") -> Home | I55: =_xlfn.XLOOKUP(A55,Orders!B:B,Orders!C:C,"Not Found") -> 5
A56: R0155 | B56: P039 | D56: 91 | E56: FALSE | F56: 45880 | G56: FALSE | H56: =_xlfn.XLOOKUP(B56,Products!A:A,Products!B:B,"Not Found") -> Sports | I56: =_xlfn.XLOOKUP(A56,Orders!B:B,Orders!C:C,"Not Found") -> 7
A57: R0092 | B57: P001 | C57: 1 | D57: 93 | E57: FALSE | F57: 45786 | G57: FALSE | H57: =_xlfn.XLOOKUP(B57,Products!A:A,Products!B:B,"Not Found") -> Electronics | I57: =_xlfn.XLOOKUP(A57,Orders!B:B,Orders!C:C,"Not Found") -> 2
A58: R0044 | B58: P033 | C58: 1 | D58: 33 | E58: TRUE | F58: 45789 | G58: FALSE | H58: =_xlfn.XLOOKUP(B58,Products!A:A,Products!B:B,"Not Found") -> Beauty | I58: =_xlfn.XLOOKUP(A58,Orders!B:B,Orders!C:C,"Not Found") -> 5
A59: R0073 | B59: P034 | C59: 4 | D59: 38 | E59: TRUE | F59: 45906 | G59: FALSE | H59: =_xlfn.XLOOKUP(B59,Products!A:A,Products!B:B,"Not Found") -> Sports | I59: =_xlfn.XLOOKUP(A59,Orders!B:B,Orders!C:C,"Not Found") -> 4
A60: R0126 | B60: P035 | C60: 3 | D60: 43 | E60: TRUE | F60: 45923 | G60: FALSE | H60: =_xlfn.XLOOKUP(B60,Products!A:A,Products!B:B,"Not Found") -> Books | I60: =_xlfn.XLOOKUP(A60,Orders!B:B,Orders!C:C,"Not Found") -> 6
A61: R0127 | B61: P012 | C61: 1 | D61: 11 | E61: TRUE | F61: 45953 | G61: FALSE | H61: =_xlfn.XLOOKUP(B61,Products!A:A,Products!B:B,"Not Found") -> Home | I61: =_xlfn.XLOOKUP(A61,Orders!B:B,Orders!C:C,"Not Found") -> 3
A62: R0019 | B62: P013 | C62: 3 | D62: 58 | E62: TRUE | F62: 45940 | G62: FALSE | H62: =_xlfn.XLOOKUP(B62,Products!A:A,Products!B:B,"Not Found") -> Beauty | I62: =_xlfn.XLOOKUP(A62,Orders!B:B,Orders!C:C,"Not Found") -> 5
A63: R0066 | B63: P055 | C63: 3 | D63: 25 | E63: TRUE | F63: 45688 | G63: FALSE | H63: =_xlfn.XLOOKUP(B63,Products!A:A,Products!B:B,"Not Found") -> Books | I63: =_xlfn.XLOOKUP(A63,Orders!B:B,Orders!C:C,"Not Found") -> 5
A64: R0156 | B64: P024 | C64: 1 | D64: 25 | E64: TRUE | F64: 45839 | G64: FALSE | H64: =_xlfn.XLOOKUP(B64,Products!A:A,Products!B:B,"Not Found") -> Sports | I64: =_xlfn.XLOOKUP(A64,Orders!B:B,Orders!C:C,"Not Found") -> 2
A65: R0186 | B65: P029 | C65: 2 | D65: 34 | E65: TRUE | F65: 45958 | G65: FALSE | H65: =_xlfn.XLOOKUP(B65,Products!A:A,Products!B:B,"Not Found") -> Sports | I65: =_xlfn.XLOOKUP(A65,Orders!B:B,Orders!C:C,"Not Found") -> 3
A66: R0095 | B66: P053 | C66: 3 | D66: 196 | E66: FALSE | F66: 45763 | G66: TRUE | H66: =_xlfn.XLOOKUP(B66,Products!A:A,Products!B:B,"Not Found") -> Beauty | I66: =_xlfn.XLOOKUP(A66,Orders!B:B,Orders!C:C,"Not Found") -> 5
A67: R0014 | B67: P053 | C67: 4 | D67: 22 | E67: FALSE | F67: 45713 | G67: FALSE | H67: =_xlfn.XLOOKUP(B67,Products!A:A,Products!B:B,"Not Found") -> Beauty | I67: =_xlfn.XLOOKUP(A67,Orders!B:B,Orders!C:C,"Not Found") -> 5
...

Sheet Sheet1
